Workbook

Sheet Sheet2
A2: Headcount & Average Salary by Department | G2: Attrition Rate
A3: Department_Name | B3: HeadCount | C3: Average Salary | F3: HeadCount | G3: Column Labels
A4: Finance | B4: 17 | C4: 87938.5 | F4: Department_Name | G4: ACTIVE | H4: LEFT | I4: RESIGNED | J4: Grand Total
A5: Human Resources | B5: 18 | C5: 85649.941 | F5: Finance | G5: 13 | H5: 2 | I5: 2 | J5: 17
A6: Information Technology | B6: 36 | C6: 80014.258 | F6: Human Resources | G6: 16 | H6: 1 | I6: 1 | J6: 18 | L6: Attrition rate
A7: Marketing | B7: 19 | C7: 85508.167 | F7: Information Technology | G7: 28 | H7: 3 | I7: 5 | J7: 36 | L7: =(GETPIVOTDATA("Cleaned EMP ID",$F$3,"Cleaned Employment_Status","LEFT")+GETPIVOTDATA("Cleaned EMP ID",$F$3,"Cleaned Employment_Status","RESIGNED"))/GETPIVOTDATA("Cleaned EMP ID",$F$3) -> 0.22
A8: Operations | B8: 29 | C8: 79786.667 | F8: Marketing | G8: 16 | H8: 3 | J8: 19
A9: Sales | B9: 31 | C9: 87282.348 | F9: Operations | G9: 22 | H9: 7 | J9: 29
F10: Sales | G10: 22 | H10: 7 | I10: 2 | J10: 31
F11: Grand Total | G11: 117 | H11: 23 | I11: 10 | J11: 150

Sheet Working_Data
A1: Emp ID | B1: First_Name | C1: Last_Name | D1: Dept Code | F1: Salary | G1: Perf_Score | H1: Employment Status | J1: Cleaned EMP ID | K1: Cleaned First_Name | L1: Cleaned Last_Name | M1: Full_Name | N1: Department_Name | O1: Cleaned Dept_Code | P1: Cleaned Hire_Date | Q1: Year_of_Service | R1: Cleaned Salary | S1: Cleaned Perf_Score | T1: Performance_Band | U1: Eligible_Bonus_Amount | V1: Cleaned Employment_Status
A2: EMP127 | B2: Emily | C2: Brown | D2: IT02 | E2: 43093 | F2: 50361 | G2: 52 | H2: active | J2: =TRIM(CLEAN(A2)) -> EMP127 | K2: =TRIM(CLEAN(PROPER(B2))) -> Emily | L2: =TRIM(CLEAN(PROPER(C2))) -> Brown | M2: =_xlfn.TEXTJOIN(" ",TRUE,K2,L2) -> Emily Brown | N2: =_xlfn.XLOOKUP(O2,Lookup_Departments!$A$2:$A$7,Lookup_Departments!$B$2:$B$7,"Not Found") -> Information Technology | O2: =IFERROR(VLOOKUP(D2,Lookup_Departments!$A$2:$B$7,1,FALSE),"Invalid") -> IT02 | P2: =IF(ISNUMBER(E2),E2,DATE(RIGHT(E2,4),LEFT(E2,2),MID(E2,4,2))) -> 43093 | Q2: =DATEDIF(P2,TODAY(),"Y") -> 8 | R2: =IF(F2="",AVERAGEIF($D$2:$D$151,D2,$F$2:$F$151),F2) -> 50361 | S2: =IF(G2="",AVERAGE($G$2:$G$158),G2) -> 52 | T2: =_xlfn.XLOOKUP(S2,Lookup_Performance!$A$2:$A$6,Lookup_Performance!$C$2:$C$6,"Not Found",-1) -> Developing | U2: =_xlfn.XLOOKUP(S2,Lookup_Performance!$A$2:$A$6,Lookup_Performance!$D$2:$D$6,"Not Found",-1) -> 0.02 | V2: =TRIM(CLEAN(UPPER(H2))) -> ACTIVE
A3: EMP046 | B3: Richard | C3: Hernandez | D3: MKT04 | E3: 44659 | F3: 112673 | H3: ACTIVE | J3: =TRIM(CLEAN(A3)) -> EMP046 | K3: =TRIM(CLEAN(PROPER(B3))) -> Richard | L3: =TRIM(CLEAN(PROPER(C3))) -> Hernandez | M3: =_xlfn.TEXTJOIN(" ",TRUE,K3,L3) -> Richard Hernandez | N3: =_xlfn.XLOOKUP(O3,Lookup_Departments!$A$2:$A$7,Lookup_Departments!$B$2:$B$7,"Not Found") -> Marketing | O3: =IFERROR(VLOOKUP(D3,Lookup_Departments!$A$2:$B$7,1,FALSE),"Invalid") -> MKT04 | P3: =IF(ISNUMBER(E3),E3,DATE(RIGHT(E3,4),LEFT(E3,2),MID(E3,4,2))) -> 44659 | Q3: =DATEDIF(P3,TODAY(),"Y") -> 4 | R3: =IF(F3="",AVERAGEIF($D$2:$D$151,D3,$F$2:$F$151),F3) -> 112673 | S3: =IF(G3="",AVERAGE($G$2:$G$158),G3) -> 68.219858 | T3: =_xlfn.XLOOKUP(S3,Lookup_Performance!$A$2:$A$6,Lookup_Performance!$C$2:$C$6,"Not Found",-1) -> Developing | U3: =_xlfn.XLOOKUP(S3,Lookup_Performance!$A$2:$A$6,Lookup_Performance!$D$2:$D$6,"Not Found",-1) -> 0.02 | V3: =TRIM(CLEAN(UPPER(H3))) -> ACTIVE
A4: EMP134 | B4: Emily | C4: Gonzalez | D4: IT02 | E4: 42431 | F4: 114425 | G4: 54 | H4: LEFT | J4: =TRIM(CLEAN(A4)) -> EMP134 | K4: =TRIM(CLEAN(PROPER(B4))) -> Emily | L4: =TRIM(CLEAN(PROPER(C4))) -> Gonzalez | M4: =_xlfn.TEXTJOIN(" ",TRUE,K4,L4) -> Emily Gonzalez | N4: =_xlfn.XLOOKUP(O4,Lookup_Departments!$A$2:$A$7,Lookup_Departments!$B$2:$B$7,"Not Found") -> Information Technology | O4: =IFERROR(VLOOKUP(D4,Lookup_Departments!$A$2:$B$7,1,FALSE),"Invalid") -> IT02 | P4: =IF(ISNUMBER(E4),E4,DATE(RIGHT(E4,4),LEFT(E4,2),MID(E4,4,2))) -> 42431 | Q4: =DATEDIF(P4,TODAY(),"Y") -> 10 | R4: =IF(F4="",AVERAGEIF($D$2:$D$151,D4,$F$2:$F$151),F4) -> 114425 | S4: =IF(G4="",AVERAGE($G$2:$G$158),G4) -> 54 | T4: =_xlfn.XLOOKUP(S4,Lookup_Performance!$A$2:$A$6,Lookup_Performance!$C$2:$C$6,"Not Found",-1) -> Developing | U4: =_xlfn.XLOOKUP(S4,Lookup_Performance!$A$2:$A$6,Lookup_Performance!$D$2:$D$6,"Not Found",-1) -> 0.02 | V4: =TRIM(CLEAN(UPPER(H4))) -> LEFT
A5: EMP139 | B5: John | C5: Martinez | D5: FIN03 | E5: 45110 | F5: 103831 | G5: 70 | H5: active | J5: =TRIM(CLEAN(A5)) -> EMP139 | K5: =TRIM(CLEAN(PROPER(B5))) -> John | L5: =TRIM(CLEAN(PROPER(C5))) -> Martinez | M5: =_xlfn.TEXTJOIN(" ",TRUE,K5,L5) -> John Martinez | N5: =_xlfn.XLOOKUP(O5,Lookup_Departments!$A$2:$A$7,Lookup_Departments!$B$2:$B$7,"Not Found") -> Finance | O5: =IFERROR(VLOOKUP(D5,Lookup_Departments!$A$2:$B$7,1,FALSE),"Invalid") -> FIN03 | P5: =IF(ISNUMBER(E5),E5,DATE(RIGHT(E5,4),LEFT(E5,2),MID(E5,4,2))) -> 45110 | Q5: =DATEDIF(P5,TODAY(),"Y") -> 3 | R5: =IF(F5="",AVERAGEIF($D$2:$D$151,D5,$F$2:$F$151),F5) -> 103831 | S5: =IF(G5="",AVERAGE($G$2:$G$158),G5) -> 70 | T5: =_xlfn.XLOOKUP(S5,Lookup_Performance!$A$2:$A$6,Lookup_Performance!$C$2:$C$6,"Not Found",-1) -> Achieving | U5: =_xlfn.XLOOKUP(S5,Lookup_Performance!$A$2:$A$6,Lookup_Performance!$D$2:$D$6,"Not Found",-1) -> 0.05 | V5: =TRIM(CLEAN(UPPER(H5))) -> ACTIVE
A6: EMP112 | B6: Thomas | C6: Smith | D6: IT02 | E6: 44977 | F6: 73785 | G6: 40 | H6: Left | J6: =TRIM(CLEAN(A6)) -> EMP112 | K6: =TRIM(CLEAN(PROPER(B6))) -> Thomas | L6: =TRIM(CLEAN(PROPER(C6))) -> Smith | M6: =_xlfn.TEXTJOIN(" ",TRUE,K6,L6) -> Thomas Smith | N6: =_xlfn.XLOOKUP(O6,Lookup_Departments!$A$2:$A$7,Lookup_Departments!$B$2:$B$7,"Not Found") -> Information Technology | O6: =IFERROR(VLOOKUP(D6,Lookup_Departments!$A$2:$B$7,1,FALSE),"Invalid") -> IT02 | P6: =IF(ISNUMBER(E6),E6,DATE(RIGHT(E6,4),LEFT(E6,2),MID(E6,4,2))) -> 44977 | Q6: =DATEDIF(P6,TODAY(),"Y") -> 3 | R6: =IF(F6="",AVERAGEIF($D$2:$D$151,D6,$F$2:$F$151),F6) -> 73785 | S6: =IF(G6="",AVERAGE($G$2:$G$158),G6) -> 40 | T6: =_xlfn.XLOOKUP(S6,Lookup_Performance!$A$2:$A$6,Lookup_Performance!$C$2:$C$6,"Not Found",-1) -> Needs Improvement | U6: =_xlfn.XLOOKUP(S6,Lookup_Performance!$A$2:$A$6,Lookup_Performance!$D$2:$D$6,"Not Found",-1) -> 0 | V6: =TRIM(CLEAN(UPPER(H6))) -> LEFT
A7: EMP030 | B7: Emily | C7: Johnson | D7: OPS06 | E7: 43892 | F7: 115882 | G7: 49 | H7: ACTIVE | J7: =TRIM(CLEAN(A7)) -> EMP030 | K7: =TRIM(CLEAN(PROPER(B7))) -> Emily | L7: =TRIM(CLEAN(PROPER(C7))) -> Johnson | M7: =_xlfn.TEXTJOIN(" ",TRUE,K7,L7) -> Emily Johnson | N7: =_xlfn.XLOOKUP(O7,Lookup_Departments!$A$2:$A$7,Lookup_Departments!$B$2:$B$7,"Not Found") -> Operations | O7: =IFERROR(VLOOKUP(D7,Lookup_Departments!$A$2:$B$7,1,FALSE),"Invalid") -> OPS06 | P7: =IF(ISNUMBER(E7),E7,DATE(RIGHT(E7,4),LEFT(E7,2),MID(E7,4,2))) -> 43892 | Q7: =DATEDIF(P7,TODAY(),"Y") -> 6 | R7: =IF(F7="",AVERAGEIF($D$2:$D$151,D7,$F$2:$F$151),F7) -> 115882 | S7: =IF(G7="",AVERAGE($G$2:$G$158),G7) -> 49 | T7: =_xlfn.XLOOKUP(S7,Lookup_Performance!$A$2:$A$6,Lookup_Performance!$C$2:$C$6,"Not Found",-1) -> Needs Improvement | U7: =_xlfn.XLOOKUP(S7,Lookup_Performance!$A$2:$A$6,Lookup_Performance!$D$2:$D$6,"Not Found",-1) -> 0 | V7: =TRIM(CLEAN(UPPER(H7))) -> ACTIVE
A8: EMP096 | B8: John | C8: Wilson | D8: OPS06 | E8: 45272 | F8: 59980 | G8: 70 | H8: Left | J8: =TRIM(CLEAN(A8)) -> EMP096 | K8: =TRIM(CLEAN(PROPER(B8))) -> John | L8: =TRIM(CLEAN(PROPER(C8))) -> Wilson | M8: =_xlfn.TEXTJOIN(" ",TRUE,K8,L8) -> John Wilson | N8: =_xlfn.XLOOKUP(O8,Lookup_Departments!$A$2:$A$7,Lookup_Departments!$B$2:$B$7,"Not Found") -> Operations | O8: =IFERROR(VLOOKUP(D8,Lookup_Departments!$A$2:$B$7,1,FALSE),"Invalid") -> OPS06 | P8: =IF(ISNUMBER(E8),E8,DATE(RIGHT(E8,4),LEFT(E8,2),MID(E8,4,2))) -> 45272 | Q8: =DATEDIF(P8,TODAY(),"Y") -> 2 | R8: =IF(F8="",AVERAGEIF($D$2:$D$151,D8,$F$2:$F$151),F8) -> 59980 | S8: =IF(G8="",AVERAGE($G$2:$G$158),G8) -> 70 | T8: =_xlfn.XLOOKUP(S8,Lookup_Performance!$A$2:$A$6,Lookup_Performance!$C$2:$C$6,"Not Found",-1) -> Achieving | U8: =_xlfn.XLOOKUP(S8,Lookup_Performance!$A$2:$A$6,Lookup_Performance!$D$2:$D$6,"Not Found",-1) -> 0.05 | V8: =TRIM(CLEAN(UPPER(H8))) -> LEFT
A9: EMP098 | B9: Jessica | C9: Smith | D9: OPS06 | E9: 44174 | F9: 68728 | G9: 45 | H9: ACTIVE | J9: =TRIM(CLEAN(A9)) -> EMP098 | K9: =TRIM(CLEAN(PROPER(B9))) -> Jessica | L9: =TRIM(CLEAN(PROPER(C9))) -> Smith | M9: =_xlfn.TEXTJOIN(" ",TRUE,K9,L9) -> Jessica Smith | N9: =_xlfn.XLOOKUP(O9,Lookup_Departments!$A$2:$A$7,Lookup_Departments!$B$2:$B$7,"Not Found") -> Operations | O9: =IFERROR(VLOOKUP(D9,Lookup_Departments!$A$2:$B$7,1,FALSE),"Invalid") -> OPS06 | P9: =IF(ISNUMBER(E9),E9,DATE(RIGHT(E9,4),LEFT(E9,2),MID(E9,4,2))) -> 44174 | Q9: =DATEDIF(P9,TODAY(),"Y") -> 5 | R9: =IF(F9="",AVERAGEIF($D$2:$D$151,D9,$F$2:$F$151),F9) -> 68728 | S9: =IF(G9="",AVERAGE($G$2:$G$158),G9) -> 45 | T9: =_xlfn.XLOOKUP(S9,Lookup_Performance!$A$2:$A$6,Lookup_Performance!$C$2:$C$6,"Not Found",-1) -> Needs Improvement | U9: =_xlfn.XLOOKUP(S9,Lookup_Performance!$A$2:$A$6,Lookup_Performance!$D$2:$D$6,"Not Found",-1) -> 0 | V9: =TRIM(CLEAN(UPPER(H9))) -> ACTIVE
A10: EMP095 | B10: Unknown | C10: Rodriguez | D10: FIN03 | E10: 43107 | F10: 102139 | G10: 79 | H10: active | J10: =TRIM(CLEAN(A10)) -> EMP095 | K10: =TRIM(CLEAN(PROPER(B10))) -> Unknown | L10: =TRIM(CLEAN(PROPER(C10))) -> Rodriguez | M10: =_xlfn.TEXTJOIN(" ",TRUE,K10,L10) -> Unknown Rodriguez | N10: =_xlfn.XLOOKUP(O10,Lookup_Departments!$A$2:$A$7,Lookup_Departments!$B$2:$B$7,"Not Found") -> Finance | O10: =IFERROR(VLOOKUP(D10,Lookup_Departments!$A$2:$B$7,1,FALSE),"Invalid") -> FIN03 | P10: =IF(ISNUMBER(E10),E10,DATE(RIGHT(E10,4),LEFT(E10,2),MID(E10,4,2))) -> 43107 | Q10: =DATEDIF(P10,TODAY(),"Y") -> 8 | R10: =IF(F10="",AVERAGEIF($D$2:$D$151,D10,$F$2:$F$151),F10) -> 102139 | S10: =IF(G10="",AVERAGE($G$2:$G$158),G10) -> 79 | T10: =_xlfn.XLOOKUP(S10,Lookup_Performance!$A$2:$A$6,Lookup_Performance!$C$2:$C$6,"Not Found",-1) -> Achieving | U10: =_xlfn.XLOOKUP(S10,Lookup_Performance!$A$2:$A$6,Lookup_Performance!$D$2:$D$6,"Not Found",-1) -> 0.05 | V10: =TRIM(CLEAN(UPPER(H10))) -> ACTIVE
A11: EMP140 | B11: Michael | C11: Martinez | D11: SAL05 | E11: 42676 | F11: 94998 | G11: 58 | H11: Active | J11: =TRIM(CLEAN(A11)) -> EMP140 | K11: =TRIM(CLEAN(PROPER(B11))) -> Michael | L11: =TRIM(CLEAN(PROPER(C11))) -> Martinez | M11: =_xlfn.TEXTJOIN(" ",TRUE,K11,L11) -> Michael Martinez | N11: =_xlfn.XLOOKUP(O11,Lookup_Departments!$A$2:$A$7,Lookup_Departments!$B$2:$B$7,"Not Found") -> Sales | O11: =IFERROR(VLOOKUP(D11,Lookup_Departments!$A$2:$B$7,1,FALSE),"Invalid") -> SAL05 | P11: =IF(ISNUMBER(E11),E11,DATE(RIGHT(E11,4),LEFT(E11,2),MID(E11,4,2))) -> 42676 | Q11: =DATEDIF(P11,TODAY(),"Y") -> 9 | R11: =IF(F11="",AVERAGEIF($D$2:$D$151,D11,$F$2:$F$151),F11) -> 94998 | S11: =IF(G11="",AVERAGE($G$2:$G$158),G11) -> 58 | T11: =_xlfn.XLOOKUP(S11,Lookup_Performance!$A$2:$A$6,Lookup_Performance!$C$2:$C$6,"Not Found",-1) -> Developing | U11: =_xlfn.XLOOKUP(S11,Lookup_Performance!$A$2:$A$6,Lookup_Performance!$D$2:$D$6,"Not Found",-1) -> 0.02 | V11: =TRIM(CLEAN(UPPER(H11))) -> ACTIVE
A12: EMP020 | B12: Emily | C12: Miller | D12: SAL05 | E12: 43911 | F12: 118635 | G12: 49 | H12: Active | J12: =TRIM(CLEAN(A12)) -> EMP020 | K12: =TRIM(CLEAN(PROPER(B12))) -> Emily | L12: =TRIM(CLEAN(PROPER(C12))) -> Miller | M12: =_xlfn.TEXTJOIN(" ",TRUE,K12,L12) -> Emily Miller | N12: =_xlfn.XLOOKUP(O12,Lookup_Departments!$A$2:$A$7,Lookup_Departments!$B$2:$B$7,"Not Found") -> Sales | O12: =IFERROR(VLOOKUP(D12,Lookup_Departments!$A$2:$B$7,1,FALSE),"Invalid") -> SAL05 | P12: =IF(ISNUMBER(E12),E12,DATE(RIGHT(E12,4),LEFT(E12,2),MID(E12,4,2))) -> 43911 | Q12: =DATEDIF(P12,TODAY(),"Y") -> 6 | R12: =IF(F12="",AVERAGEIF($D$2:$D$151,D12,$F$2:$F$151),F12) -> 118635 | S12: =IF(G12="",AVERAGE($G$2:$G$158),G12) -> 49 | T12: =_xlfn.XLOOKUP(S12,Lookup_Performance!$A$2:$A$6,Lookup_Performance!$C$2:$C$6,"Not Found",-1) -> Needs Improvement | U12: =_xlfn.XLOOKUP(S12,Lookup_Performance!$A$2:$A$6,Lookup_Performance!$D$2:$D$6,"Not Found",-1) -> 0 | V12: =TRIM(CLEAN(UPPER(H12))) -> ACTIVE
A13: EMP057 | B13: Emily | C13: Hernandez | D13: IT02 | E13: 42425 | F13: 76918 | G13: 62 | H13: ACTIVE | J13: =TRIM(CLEAN(A13)) -> EMP057 | K13: =TRIM(CLEAN(PROPER(B13))) -> Emily | L13: =TRIM(CLEAN(PROPER(C13))) -> Hernandez | M13: =_xlfn.TEXTJOIN(" ",TRUE,K13,L13) -> Emily Hernandez | N13: =_xlfn.XLOOKUP(O13,Lookup_Departments!$A$2:$A$7,Lookup_Departments!$B$2:$B$7,"Not Found") -> Information Technology | O13: =IFERROR(VLOOKUP(D13,Lookup_Departments!$A$2:$B$7,1,FALSE),"Invalid") -> IT02 | P13: =IF(ISNUMBER(E13),E13,DATE(RIGHT(E13,4),LEFT(E13,2),MID(E13,4,2))) -> 42425 | Q13: =DATEDIF(P13,TODAY(),"Y") -> 10 | R13: =IF(F13="",AVERAGEIF($D$2:$D$151,D13,$F$2:$F$151),F13) -> 76918 | S13: =IF(G13="",AVERAGE($G$2:$G$158),G13) -> 62 | T13: =_xlfn.XLOOKUP(S13,Lookup_Performance!$A$2:$A$6,Lookup_Performance!$C$2:$C$6,"Not Found",-1) -> Developing | U13: =_xlfn.XLOOKUP(S13,Lookup_Performance!$A$2:$A$6,Lookup_Performance!$D$2:$D$6,"Not Found",-1) -> 0.02 | V13: =TRIM(CLEAN(UPPER(H13))) -> ACTIVE
A14: EMP016 | B14: Jane | C14: Williams | D14: MKT04 | E14: 44364 | F14: 61408 | G14: 48 | H14: ACTIVE | J14: =TRIM(CLEAN(A14)) -> EMP016 | K14: =TRIM(CLEAN(PROPER(B14))) -> Jane | L14: =TRIM(CLEAN(PROPER(C14))) -> Williams | M14: =_xlfn.TEXTJOIN(" ",TRUE,K14,L14) -> Jane Williams | N14: =_xlfn.XLOOKUP(O14,Lookup_Departments!$A$2:$A$7,Lookup_Departments!$B$2:$B$7,"Not Found") -> Marketing | O14: =IFERROR(VLOOKUP(D14,Lookup_Departments!$A$2:$B$7,1,FALSE),"Invalid") -> MKT04 | P14: =IF(ISNUMBER(E14),E14,DATE(RIGHT(E14,4),LEFT(E14,2),MID(E14,4,2))) -> 44364 | Q14: =DATEDIF(P14,TODAY(),"Y") -> 5 | R14: =IF(F14="",AVERAGEIF($D$2:$D$151,D14,$F$2:$F$151),F14) -> 61408 | S14: =IF(G14="",AVERAGE($G$2:$G$158),G14) -> 48 | T14: =_xlfn.XLOOKUP(S14,Lookup_Performance!$A$2:$A$6,Lookup_Performance!$C$2:$C$6,"Not Found",-1) -> Needs Improvement | U14: =_xlfn.XLOOKUP(S14,Lookup_Performance!$A$2:$A$6,Lookup_Performance!$D$2:$D$6,"Not Found",-1) -> 0 | V14: =TRIM(CLEAN(UPPER(H14))) -> ACTIVE
A15: EMP070 | B15: Jane | C15: Miller | D15: MKT04 | E15: 44001 | F15: 99990 | G15: 54 | H15: ACTIVE | J15: =TRIM(CLEAN(A15)) -> EMP070 | K15: =TRIM(CLEAN(PROPER(B15))) -> Jane | L15: =TRIM(CLEAN(PROPER(C15))) -> Miller | M15: =_xlfn.TEXTJOIN(" ",TRUE,K15,L15) -> Jane Miller | N15: =_xlfn.XLOOKUP(O15,Lookup_Departments!$A$2:$A$7,Lookup_Departments!$B$2:$B$7,"Not Found") -> Marketing | O15: =IFERROR(VLOOKUP(D15,Lookup_Departments!$A$2:$B$7,1,FALSE),"Invalid") -> MKT04 | P15: =IF(ISNUMBER(E15),E15,DATE(RIGHT(E15,4),LEFT(E15,2),MID(E15,4,2))) -> 44001 | Q15: =DATEDIF(P15,TODAY(),"Y") -> 6 | R15: =IF(F15="",AVERAGEIF($D$2:$D$151,D15,$F$2:$F$151),F15) -> 99990 | S15: =IF(G15="",AVERAGE($G$2:$G$158),G15) -> 54 | T15: =_xlfn.XLOOKUP(S15,Lookup_Performance!$A$2:$A$6,Lookup_Performance!$C$2:$C$6,"Not Found",-1) -> Developing | U15: =_xlfn.XLOOKUP(S15,Lookup_Performance!$A$2:$A$6,Lookup_Performance!$D$2:$D$6,"Not Found",-1) -> 0.02 | V15: =TRIM(CLEAN(UPPER(H15))) -> ACTIVE
A16: EMP025 | B16: Robert | C16: Jones | D16: MKT04 | E16: 43820 | F16: 80385 | H16: active | J16: =TRIM(CLEAN(A16)) -> EMP025 | K16: =TRIM(CLEAN(PROPER(B16))) -> Robert | L16: =TRIM(CLEAN(PROPER(C16))) -> Jones | M16: =_xlfn.TEXTJOIN(" ",TRUE,K16,L16) -> Robert Jones | N16: =_xlfn.XLOOKUP(O16,Lookup_Departments!$A$2:$A$7,Lookup_Departments!$B$2:$B$7,"Not Found") -> Marketing | O16: =IFERROR(VLOOKUP(D16,Lookup_Departments!$A$2:$B$7,1,FALSE),"Invalid") -> MKT04 | P16: =IF(ISNUMBER(E16),E16,DATE(RIGHT(E16,4),LEFT(E16,2),MID(E16,4,2))) -> 43820 | Q16: =DATEDIF(P16,TODAY(),"Y") -> 6 | R16: =IF(F16="",AVERAGEIF($D$2:$D$151,D16,$F$2:$F$151),F16) -> 80385 | S16: =IF(G16="",AVERAGE($G$2:$G$158),G16) -> 68.219858 | T16: =_xlfn.XLOOKUP(S16,Lookup_Performance!$A$2:$A$6,Lookup_Performance!$C$2:$C$6,"Not Found",-1) -> Developing | U16: =_xlfn.XLOOKUP(S16,Lookup_Performance!$A$2:$A$6,Lookup_Performance!$D$2:$D$6,"Not Found",-1) -> 0.02 | V16: =TRIM(CLEAN(UPPER(H16))) -> ACTIVE
A17: EMP031 | B17: Thomas | C17: Rodriguez | D17: SAL05 | E17: 45169 | F17: 65290 | G17: 77 | H17: active | J17: =TRIM(CLEAN(A17)) -> EMP031 | K17: =TRIM(CLEAN(PROPER(B17))) -> Thomas | L17: =TRIM(CLEAN(PROPER(C17))) -> Rodriguez | M17: =_xlfn.TEXTJOIN(" ",TRUE,K17,L17) -> Thomas Rodriguez | N17: =_xlfn.XLOOKUP(O17,Lookup_Departments!$A$2:$A$7,Lookup_Departments!$B$2:$B$7,"Not Found") -> Sales | O17: =IFERROR(VLOOKUP(D17,Lookup_Departments!$A$2:$B$7,1,FALSE),"Invalid") -> SAL05 | P17: =IF(ISNUMBER(E17),E17,DATE(RIGHT(E17,4),LEFT(E17,2),MID(E17,4,2))) -> 45169 | Q17: =DATEDIF(P17,TODAY(),"Y") -> 2 | R17: =IF(F17="",AVERAGEIF($D$2:$D$151,D17,$F$2:$F$151),F17) -> 65290 | S17: =IF(G17="",AVERAGE($G$2:$G$158),G17) -> 77 | T17: =_xlfn.XLOOKUP(S17,Lookup_Performance!$A$2:$A$6,Lookup_Performance!$C$2:$C$6,"Not Found",-1) -> Achieving | U17: =_xlfn.XLOOKUP(S17,Lookup_Performance!$A$2:$A$6,Lookup_Performance!$D$2:$D$6,"Not Found",-1) -> 0.05 | V17: =TRIM(CLEAN(UPPER(H17))) -> ACTIVE
A18: EMP126 | B18: Emily | C18: Davis | D18: IT02 | E18: 42337 | F18: 105765 | G18: 42 | H18: Active | J18: =TRIM(CLEAN(A18)) -> EMP126 | K18: =TRIM(CLEAN(PROPER(B18))) -> Emily | L18: =TRIM(CLEAN(PROPER(C18))) -> Davis | M18: =_xlfn.TEXTJOIN(" ",TRUE,K18,L18) -> Emily Davis | N18: =_xlfn.XLOOKUP(O18,Lookup_Departments!$A$2:$A$7,Lookup_Departments!$B$2:$B$7,"Not Found") -> Information Technology | O18: =IFERROR(VLOOKUP(D18,Lookup_Departments!$A$2:$B$7,1,FALSE),"Invalid") -> IT02 | P18: =IF(ISNUMBER(E18),E18,DATE(RIGHT(E18,4),LEFT(E18,2),MID(E18,4,2))) -> 42337 | Q18: =DATEDIF(P18,TODAY(),"Y") -> 10 | R18: =IF(F18="",AVERAGEIF($D$2:$D$151,D18,$F$2:$F$151),F18) -> 105765 | S18: =IF(G18="",AVERAGE($G$2:$G$158),G18) -> 42 | T18: =_xlfn.XLOOKUP(S18,Lookup_Performance!$A$2:$A$6,Lookup_Performance!$C$2:$C$6,"Not Found",-1) -> Needs Improvement | U18: =_xlfn.XLOOKUP(S18,Lookup_Performance!$A$2:$A$6,Lookup_Performance!$D$2:$D$6,"Not Found",-1) -> 0 | V18: =TRIM(CLEAN(UPPER(H18))) -> ACTIVE
A19: EMP109 | B19: James | C19: Martinez | D19: SAL05 | E19: 42899 | F19: 102921 | G19: 49 | H19: ACTIVE | J19: =TRIM(CLEAN(A19)) -> EMP109 | K19: =TRIM(CLEAN(PROPER(B19))) -> James | L19: =TRIM(CLEAN(PROPER(C19))) -> Martinez | M19: =_xlfn.TEXTJOIN(" ",TRUE,K19,L19) -> James Martinez | N19: =_xlfn.XLOOKUP(O19,Lookup_Departments!$A$2:$A$7,Lookup_Departments!$B$2:$B$7,"Not Found") -> Sales | O19: =IFERROR(VLOOKUP(D19,Lookup_Departments!$A$2:$B$7,1,FALSE),"Invalid") -> SAL05 | P19: =IF(ISNUMBER(E19),E19,DATE(RIGHT(E19,4),LEFT(E19,2),MID(E19,4,2))) -> 42899 | Q19: =DATEDIF(P19,TODAY(),"Y") -> 9 | R19: =IF(F19="",AVERAGEIF($D$2:$D$151,D19,$F$2:$F$151),F19) -> 102921 | S19: =IF(G19="",AVERAGE($G$2:$G$158),G19) -> 49 | T19: =_xlfn.XLOOKUP(S19,Lookup_Performance!$A$2:$A$6,Lookup_Performance!$C$2:$C$6,"Not Found",-1) -> Needs Improvement | U19: =_xlfn.XLOOKUP(S19,Lookup_Performance!$A$2:$A$6,Lookup_Performance!$D$2:$D$6,"Not Found",-1) -> 0 | V19: =TRIM(CLEAN(UPPER(H19))) -> ACTIVE
A20: EMP066 | B20: Ashley | C20: Lopez | D20: MKT04 | E20: 43235 | F20: 73984 | G20: 62 | H20: ACTIVE | J20: =TRIM(CLEAN(A20)) -> EMP066 | K20: =TRIM(CLEAN(PROPER(B20))) -> Ashley | L20: =TRIM(CLEAN(PROPER(C20))) -> Lopez | M20: =_xlfn.TEXTJOIN(" ",TRUE,K20,L20) -> Ashley Lopez | N20: =_xlfn.XLOOKUP(O20,Lookup_Departments!$A$2:$A$7,Lookup_Departments!$B$2:$B$7,"Not Found") -> Marketing | O20: =IFERROR(VLOOKUP(D20,Lookup_Departments!$A$2:$B$7,1,FALSE),"Invalid") -> MKT04 | P20: =IF(ISNUMBER(E20),E20,DATE(RIGHT(E20,4),LEFT(E20,2),MID(E20,4,2))) -> 43235 | Q20: =DATEDIF(P20,TODAY(),"Y") -> 8 | R20: =IF(F20="",AVERAGEIF($D$2:$D$151,D20,$F$2:$F$151),F20) -> 73984 | S20: =IF(G20="",AVERAGE($G$2:$G$158),G20) -> 62 | T20: =_xlfn.XLOOKUP(S20,Lookup_Performance!$A$2:$A$6,Lookup_Performance!$C$2:$C$6,"Not Found",-1) -> Developing | U20: =_xlfn.XLOOKUP(S20,Lookup_Performance!$A$2:$A$6,Lookup_Performance!$D$2:$D$6,"Not Found",-1) -> 0.02 | V20: =TRIM(CLEAN(UPPER(H20))) -> ACTIVE
A21: EMP120 | B21: Amanda | C21: Gonzalez | D21: IT02 | E21: 42575 | G21: 93 | H21: ACTIVE | J21: =TRIM(CLEAN(A21)) -> EMP120 | K21: =TRIM(CLEAN(PROPER(B21))) -> Amanda | L21: =TRIM(CLEAN(PROPER(C21))) -> Gonzalez | M21: =_xlfn.TEXTJOIN(" ",TRUE,K21,L21) -> Amanda Gonzalez | N21: =_xlfn.XLOOKUP(O21,Lookup_Departments!$A$2:$A$7,Lookup_Departments!$B$2:$B$7,"Not Found") -> Information Technology | O21: =IFERROR(VLOOKUP(D21,Lookup_Departments!$A$2:$B$7,1,FALSE),"Invalid") -> IT02 | P21: =IF(ISNUMBER(E21),E21,DATE(RIGHT(E21,4),LEFT(E21,2),MID(E21,4,2))) -> 42575 | Q21: =DATEDIF(P21,TODAY(),"Y") -> 9 | R21: =IF(F21="",AVERAGEIF($D$2:$D$151,D21,$F$2:$F$151),F21) -> 80014.258 | S21: =IF(G21="",AVERAGE($G$2:$G$158),G21) -> 93 | T21: =_xlfn.XLOOKUP(S21,Lookup_Performance!$A$2:$A$6,Lookup_Performance!$C$2:$C$6,"Not Found",-1) -> Exceeding | U21: =_xlfn.XLOOKUP(S21,Lookup_Performance!$A$2:$A$6,Lookup_Performance!$D$2:$D$6,"Not Found",-1) -> 0.08 | V21: =TRIM(CLEAN(UPPER(H21))) -> ACTIVE
A22: EMP019 | B22: Michael | C22: Hernandez | D22: FIN03 | E22: 43076 | F22: 118527 | G22: 75 | H22: ACTIVE | J22: =TRIM(CLEAN(A22)) -> EMP019 | K22: =TRIM(CLEAN(PROPER(B22))) -> Michael | L22: =TRIM(CLEAN(PROPER(C22))) -> Hernandez | M22: =_xlfn.TEXTJOIN(" ",TRUE,K22,L22) -> Michael Hernandez | N22: =_xlfn.XLOOKUP(O22,Lookup_Departments!$A$2:$A$7,Lookup_Departments!$B$2:$B$7,"Not Found") -> Finance | O22: =IFERROR(VLOOKUP(D22,Lookup_Departments!$A$2:$B$7,1,FALSE),"Invalid") -> FIN03 | P22: =IF(ISNUMBER(E22),E22,DATE(RIGHT(E22,4),LEFT(E22,2),MID(E22,4,2))) -> 43076 | Q22: =DATEDIF(P22,TODAY(),"Y") -> 8 | R22: =IF(F22="",AVERAGEIF($D$2:$D$151,D22,$F$2:$F$151),F22) -> 118527 | S22: =IF(G22="",AVERAGE($G$2:$G$158),G22) -> 75 | T22: =_xlfn.XLOOKUP(S22,Lookup_Performance!$A$2:$A$6,Lookup_Performance!$C$2:$C$6,"Not Found",-1) -> Achieving | U22: =_xlfn.XLOOKUP(S22,Lookup_Performance!$A$2:$A$6,Lookup_Performance!$D$2:$D$6,"Not Found",-1) -> 0.05 | V22: =TRIM(CLEAN(UPPER(H22))) -> ACTIVE
A23: EMP013 | B23: Richard | C23: Hernandez | D23: MKT04 | E23: 44353 | F23: 107871 | G23: 50 | H23: ACTIVE | J23: =TRIM(CLEAN(A23)) -> EMP013 | K23: =TRIM(CLEAN(PROPER(B23))) -> Richard | L23: =TRIM(CLEAN(PROPER(C23))) -> Hernandez | M23: =_xlfn.TEXTJOIN(" ",TRUE,K23,L23) -> Richard Hernandez | N23: =_xlfn.XLOOKUP(O23,Lookup_Departments!$A$2:$A$7,Lookup_Departments!$B$2:$B$7,"Not Found") -> Marketing | O23: =IFERROR(VLOOKUP(D23,Lookup_Departments!$A$2:$B$7,1,FALSE),"Invalid") -> MKT04 | P23: =IF(ISNUMBER(E23),E23,DATE(RIGHT(E23,4),LEFT(E23,2),MID(E23,4,2))) -> 44353 | Q23: =DATEDIF(P23,TODAY(),"Y") -> 5 | R23: =IF(F23="",AVERAGEIF($D$2:$D$151,D23,$F$2:$F$151),F23) -> 107871 | S23: =IF(G23="",AVERAGE($G$2:$G$158),G23) -> 50 | T23: =_xlfn.XLOOKUP(S23,Lookup_Performance!$A$2:$A$6,Lookup_Performance!$C$2:$C$6,"Not Found",-1) -> Developing | U23: =_xlfn.XLOOKUP(S23,Lookup_Performance!$A$2:$A$6,Lookup_Performance!$D$2:$D$6,"Not Found",-1) -> 0.02 | V23: =TRIM(CLEAN(UPPER(H23))) -> ACTIVE
A24: EMP010 | B24: Michael | C24: Rodriguez | D24: IT02 | E24: 44815 | F24: 93956 | G24: 88 | H24: active | J24: =TRIM(CLEAN(A24)) -> EMP010 | K24: =TRIM(CLEAN(PROPER(B24))) -> Michael | L24: =TRIM(CLEAN(PROPER(C24))) -> Rodriguez | M24: =_xlfn.TEXTJOIN(" ",TRUE,K24,L24) -> Michael Rodriguez | N24: =_xlfn.XLOOKUP(O24,Lookup_Departments!$A$2:$A$7,Lookup_Departments!$B$2:$B$7,"Not Found") -> Information Technology | O24: =IFERROR(VLOOKUP(D24,Lookup_Departments!$A$2:$B$7,1,FALSE),"Invalid") -> IT02 | P24: =IF(ISNUMBER(E24),E24,DATE(RIGHT(E24,4),LEFT(E24,2),MID(E24,4,2))) -> 44815 | Q24: =DATEDIF(P24,TODAY(),"Y") -> 3 | R24: =IF(F24="",AVERAGEIF($D$2:$D$151,D24,$F$2:$F$151),F24) -> 93956 | S24: =IF(G24="",AVERAGE($G$2:$G$158),G24) -> 88 | T24: =_xlfn.XLOOKUP(S24,Lookup_Performance!$A$2:$A$6,Lookup_Performance!$C$2:$C$6,"Not Found",-1) -> Exceeding | U24: =_xlfn.XLOOKUP(S24,Lookup_Performance!$A$2:$A$6,Lookup_Performance!$D$2:$D$6,"Not Found",-1) -> 0.08 | V24: =TRIM(CLEAN(UPPER(H24))) -> ACTIVE
A25: EMP032 | B25: Jessica | C25: Johnson | D25: FIN03 | E25: 42565 | F25: 100851 | G25: 50 | H25: LEFT | J25: =TRIM(CLEAN(A25)) -> EMP032 | K25: =TRIM(CLEAN(PROPER(B25))) -> Jessica | L25: =TRIM(CLEAN(PROPER(C25))) -> Johnson | M25: =_xlfn.TEXTJOIN(" ",TRUE,K25,L25) -> Jessica Johnson | N25: =_xlfn.XLOOKUP(O25,Lookup_Departments!$A$2:$A$7,Lookup_Departments!$B$2:$B$7,"Not Found") -> Finance | O25: =IFERROR(VLOOKUP(D25,Lookup_Departments!$A$2:$B$7,1,FALSE),"Invalid") -> FIN03 | P25: =IF(ISNUMBER(E25),E25,DATE(RIGHT(E25,4),LEFT(E25,2),MID(E25,4,2))) -> 42565 | Q25: =DATEDIF(P25,TODAY(),"Y") -> 9 | R25: =IF(F25="",AVERAGEIF($D$2:$D$151,D25,$F$2:$F$151),F25) -> 100851 | S25: =IF(G25="",AVERAGE($G$2:$G$158),G25) -> 50 | T25: =_xlfn.XLOOKUP(S25,Lookup_Performance!$A$2:$A$6,Lookup_Performance!$C$2:$C$6,"Not Found",-1) -> Developing | U25: =_xlfn.XLOOKUP(S25,Lookup_Performance!$A$2:$A$6,Lookup_Performance!$D$2:$D$6,"Not Found",-1) -> 0.02 | V25: =TRIM(CLEAN(UPPER(H25))) -> LEFT
A26: EMP082 | B26: Ashley | C26: Williams | D26: SAL05 | E26: 44728 | F26: 68655 | G26: 64 | H26: ACTIVE | J26: =TRIM(CLEAN(A26)) -> EMP082 | K26: =TRIM(CLEAN(PROPER(B26))) -> Ashley | L26: =TRIM(CLEAN(PROPER(C26))) -> Williams | M26: =_xlfn.TEXTJOIN(" ",TRUE,K26,L26) -> Ashley Williams | N26: =_xlfn.XLOOKUP(O26,Lookup_Departments!$A$2:$A$7,Lookup_Departments!$B$2:$B$7,"Not Found") -> Sales | O26: =IFERROR(VLOOKUP(D26,Lookup_Departments!$A$2:$B$7,1,FALSE),"Invalid") -> SAL05 | P26: =IF(ISNUMBER(E26),E26,DATE(RIGHT(E26,4),LEFT(E26,2),MID(E26,4,2))) -> 44728 | Q26: =DATEDIF(P26,TODAY(),"Y") -> 4 | R26: =IF(F26="",AVERAGEIF($D$2:$D$151,D26,$F$2:$F$151),F26) -> 68655 | S26: =IF(G26="",AVERAGE($G$2:$G$158),G26) -> 64 | T26: =_xlfn.XLOOKUP(S26,Lookup_Performance!$A$2:$A$6,Lookup_Performance!$C$2:$C$6,"Not Found",-1) -> Developing | U26: =_xlfn.XLOOKUP(S26,Lookup_Performance!$A$2:$A$6,Lookup_Performance!$D$2:$D$6,"Not Found",-1) -> 0.02 | V26: =TRIM(CLEAN(UPPER(H26))) -> ACTIVE
A27: EMP052 | B27: Unknown | C27: Williams | D27: SAL05 | E27: 45134 | F27: 81205 | G27: 32 | H27: active | J27: =TRIM(CLEAN(A27)) -> EMP052 | K27: =TRIM(CLEAN(PROPER(B27))) -> Unknown | L27: =TRIM(CLEAN(PROPER(C27))) -> Williams | M27: =_xlfn.TEXTJOIN(" ",TRUE,K27,L27) -> Unknown Williams | N27: =_xlfn.XLOOKUP(O27,Lookup_Departments!$A$2:$A$7,Lookup_Departments!$B$2:$B$7,"Not Found") -> Sales | O27: =IFERROR(VLOOKUP(D27,Lookup_Departments!$A$2:$B$7,1,FALSE),"Invalid") -> SAL05 | P27: =IF(ISNUMBER(E27),E27,DATE(RIGHT(E27,4),LEFT(E27,2),MID(E27,4,2))) -> 45134 | Q27: =DATEDIF(P27,TODAY(),"Y") -> 2 | R27: =IF(F27="",AVERAGEIF($D$2:$D$151,D27,$F$2:$F$151),F27) -> 81205 | S27: =IF(G27="",AVERAGE($G$2:$G$158),G27) -> 32 | T27: =_xlfn.XLOOKUP(S27,Lookup_Performance!$A$2:$A$6,Lookup_Performance!$C$2:$C$6,"Not Found",-1) -> Needs Improvement | U27: =_xlfn.XLOOKUP(S27,Lookup_Performance!$A$2:$A$6,Lookup_Performance!$D$2:$D$6,"Not Found",-1) -> 0 | V27: =TRIM(CLEAN(UPPER(H27))) -> ACTIVE
A28: EMP129 | B28: John | C28: Wilson | D28: SAL05 | E28: 09/24/2019 | F28: 77610 | G28: 59 | H28: ACTIVE | J28: =TRIM(CLEAN(A28)) -> EMP129 | K28: =TRIM(CLEAN(PROPER(B28))) -> John | L28: =TRIM(CLEAN(PROPER(C28))) -> Wilson | M28: =_xlfn.TEXTJOIN(" ",TRUE,K28,L28) -> John Wilson | N28: =_xlfn.XLOOKUP(O28,Lookup_Departments!$A$2:$A$7,Lookup_Departments!$B$2:$B$7,"Not Found") -> Sales | O28: =IFERROR(VLOOKUP(D28,Lookup_Departments!$A$2:$B$7,1,FALSE),"Invalid") -> SAL05 | P28: =IF(ISNUMBER(E28),E28,DATE(RIGHT(E28,4),LEFT(E28,2),MID(E28,4,2))) -> 43732 | Q28: =DATEDIF(P28,TODAY(),"Y") -> 6 | R28: =IF(F28="",AVERAGEIF($D$2:$D$151,D28,$F$2:$F$151),F28) -> 77610 | S28: =IF(G28="",AVERAGE($G$2:$G$158),G28) -> 59 | T28: =_xlfn.XLOOKUP(S28,Lookup_Performance!$A$2:$A$6,Lookup_Performance!$C$2:$C$6,"Not Found",-1) -> Developing | U28: =_xlfn.XLOOKUP(S28,Lookup_Performance!$A$2:$A$6,Lookup_Performance!$D$2:$D$6,"Not Found",-1) -> 0.02 | V28: =TRIM(CLEAN(UPPER(H28))) -> ACTIVE
A29: EMP146 | B29: Thomas | C29: Rodriguez | D29: IT02 | E29: 44765 | F29: 50873 | G29: 88 | H29: ACTIVE | J29: =TRIM(CLEAN(A29)) -> EMP146 | K29: =TRIM(CLEAN(PROPER(B29))) -> Thomas | L29: =TRIM(CLEAN(PROPER(C29))) -> Rodriguez | M29: =_xlfn.TEXTJOIN(" ",TRUE,K29,L29) -> Thomas Rodriguez | N29: =_xlfn.XLOOKUP(O29,Lookup_Departments!$A$2:$A$7,Lookup_Departments!$B$2:$B$7,"Not Found") -> Information Technology | O29: =IFERROR(VLOOKUP(D29,Lookup_Departments!$A$2:$B$7,1,FALSE),"Invalid") -> IT02 | P29: =IF(ISNUMBER(E29),E29,DATE(RIGHT(E29,4),LEFT(E29,2),MID(E29,4,2))) -> 44765 | Q29: =DATEDIF(P29,TODAY(),"Y") -> 3 | R29: =IF(F29="",AVERAGEIF($D$2:$D$151,D29,$F$2:$F$151),F29) -> 50873 | S29: =IF(G29="",AVERAGE($G$2:$G$158),G29) -> 88 | T29: =_xlfn.XLOOKUP(S29,Lookup_Performance!$A$2:$A$6,Lookup_Performance!$C$2:$C$6,"Not Found",-1) -> Exceeding | U29: =_xlfn.XLOOKUP(S29,Lookup_Performance!$A$2:$A$6,Lookup_Performance!$D$2:$D$6,"Not Found",-1) -> 0.08 | V29: =TRIM(CLEAN(UPPER(H29))) -> ACTIVE
A30: EMP099 | B30: Michael | C30: Wilson | D30: FIN03 | E30: 43233 | F30: 85312 | G30: 90 | H30: Active | J30: =TRIM(CLEAN(A30)) -> EMP099 | K30: =TRIM(CLEAN(PROPER(B30))) -> Michael | L30: =TRIM(CLEAN(PROPER(C30))) -> Wilson | M30: =_xlfn.TEXTJOIN(" ",TRUE,K30,L30) -> Michael Wilson | N30: =_xlfn.XLOOKUP(O30,Lookup_Departments!$A$2:$A$7,Lookup_Departments!$B$2:$B$7,"Not Found") -> Finance | O30: =IFERROR(VLOOKUP(D30,Lookup_Departments!$A$2:$B$7,1,FALSE),"Invalid") -> FIN03 | P30: =IF(ISNUMBER(E30),E30,DATE(RIGHT(E30,4),LEFT(E30,2),MID(E30,4,2))) -> 43233 | Q30: =DATEDIF(P30,TODAY(),"Y") -> 8 | R30: =IF(F30="",AVERAGEIF($D$2:$D$151,D30,$F$2:$F$151),F30) -> 85312 | S30: =IF(G30="",AVERAGE($G$2:$G$158),G30) -> 90 | T30: =_xlfn.XLOOKUP(S30,Lookup_Performance!$A$2:$A$6,Lookup_Performance!$C$2:$C$6,"Not Found",-1) -> Exceeding | U30: =_xlfn.XLOOKUP(S30,Lookup_Performance!$A$2:$A$6,Lookup_Performance!$D$2:$D$6,"Not Found",-1) -> 0.08 | V30: =TRIM(CLEAN(UPPER(H30))) -> ACTIVE
A31: EMP015 | B31: John | C31: Rodriguez | D31: SAL05 | E31: 42202 | G31: 66 | H31: active | J31: =TRIM(CLEAN(A31)) -> EMP015 | K31: =TRIM(CLEAN(PROPER(B31))) -> John | L31: =TRIM(CLEAN(PROPER(C31))) -> Rodriguez | M31: =_xlfn.TEXTJOIN(" ",TRUE,K31,L31) -> John Rodriguez | N31: =_xlfn.XLOOKUP(O31,Lookup_Departments!$A$2:$A$7,Lookup_Departments!$B$2:$B$7,"Not Found") -> Sales | O31: =IFERROR(VLOOKUP(D31,Lookup_Departments!$A$2:$B$7,1,FALSE),"Invalid") -> SAL05 | P31: =IF(ISNUMBER(E31),E31,DATE(RIGHT(E31,4),LEFT(E31,2),MID(E31,4,2))) -> 42202 | Q31: =DATEDIF(P31,TODAY(),"Y") -> 10 | R31: =IF(F31="",AVERAGEIF($D$2:$D$151,D31,$F$2:$F$151),F31) -> 87282.348 | S31: =IF(G31="",AVERAGE($G$2:$G$158),G31) -> 66 | T31: =_xlfn.XLOOKUP(S31,Lookup_Performance!$A$2:$A$6,Lookup_Performance!$C$2:$C$6,"Not Found",-1) -> Developing | U31: =_xlfn.XLOOKUP(S31,Lookup_Performance!$A$2:$A$6,Lookup_Performance!$D$2:$D$6,"Not Found",-1) -> 0.02 | V31: =TRIM(CLEAN(UPPER(H31))) -> ACTIVE
A32: EMP076 | B32: Thomas | C32: Hernandez | D32: OPS06 | E32: 42221 | F32: 97055 | G32: 68 | H32: active | J32: =TRIM(CLEAN(A32)) -> EMP076 | K32: =TRIM(CLEAN(PROPER(B32))) -> Thomas | L32: =TRIM(CLEAN(PROPER(C32))) -> Hernandez | M32: =_xlfn.TEXTJOIN(" ",TRUE,K32,L32) -> Thomas Hernandez | N32: =_xlfn.XLOOKUP(O32,Lookup_Departments!$A$2:$A$7,Lookup_Departments!$B$2:$B$7,"Not Found") -> Operations | O32: =IFERROR(VLOOKUP(D32,Lookup_Departments!$A$2:$B$7,1,FALSE),"Invalid") -> OPS06 | P32: =IF(ISNUMBER(E32),E32,DATE(RIGHT(E32,4),LEFT(E32,2),MID(E32,4,2))) -> 42221 | Q32: =DATEDIF(P32,TODAY(),"Y") -> 10 | R32: =IF(F32="",AVERAGEIF($D$2:$D$151,D32,$F$2:$F$151),F32) -> 97055 | S32: =IF(G32="",AVERAGE($G$2:$G$158),G32) -> 68 | T32: =_xlfn.XLOOKUP(S32,Lookup_Performance!$A$2:$A$6,Lookup_Performance!$C$2:$C$6,"Not Found",-1) -> Developing | U32: =_xlfn.XLOOKUP(S32,Lookup_Performance!$A$2:$A$6,Lookup_Performance!$D$2:$D$6,"Not Found",-1) -> 0.02 | V32: =TRIM(CLEAN(UPPER(H32))) -> ACTIVE
A33: EMP137 | B33: Michael | C33: Johnson | D33: IT02 | E33: 45195 | F33: 66069 | G33: 80 | H33: ACTIVE | J33: =TRIM(CLEAN(A33)) -> EMP137 | K33: =TRIM(CLEAN(PROPER(B33))) -> Michael | L33: =TRIM(CLEAN(PROPER(C33))) -> Johnson | M33: =_xlfn.TEXTJOIN(" ",TRUE,K33,L33) -> Michael Johnson | N33: =_xlfn.XLOOKUP(O33,Lookup_Departments!$A$2:$A$7,Lookup_Departments!$B$2:$B$7,"Not Found") -> Information Technology | O33: =IFERROR(VLOOKUP(D33,Lookup_Departments!$A$2:$B$7,1,FALSE),"Invalid") -> IT02 | P33: =IF(ISNUMBER(E33),E33,DATE(RIGHT(E33,4),LEFT(E33,2),MID(E33,4,2))) -> 45195 | Q33: =DATEDIF(P33,TODAY(),"Y") -> 2 | R33: =IF(F33="",AVERAGEIF($D$2:$D$151,D33,$F$2:$F$151),F33) -> 66069 | S33: =IF(G33="",AVERAGE($G$2:$G$158),G33) -> 80 | T33: =_xlfn.XLOOKUP(S33,Lookup_Performance!$A$2:$A$6,Lookup_Performance!$C$2:$C$6,"Not Found",-1) -> Achieving | U33: =_xlfn.XLOOKUP(S33,Lookup_Performance!$A$2:$A$6,Lookup_Performance!$D$2:$D$6,"Not Found",-1) -> 0.05 | V33: =TRIM(CLEAN(UPPER(H33))) -> ACTIVE
A34: EMP056 | B34: Sarah | C34: Brown | D34: IT02 | E34: 43626 | F34: 90157 | G34: 72 | H34: ACTIVE | J34: =TRIM(CLEAN(A34)) -> EMP056 | K34: =TRIM(CLEAN(PROPER(B34))) -> Sarah | L34: =TRIM(CLEAN(PROPER(C34))) -> Brown | M34: =_xlfn.TEXTJOIN(" ",TRUE,K34,L34) -> Sarah Brown | N34: =_xlfn.XLOOKUP(O34,Lookup_Departments!$A$2:$A$7,Lookup_Departments!$B$2:$B$7,"Not Found") -> Information Technology | O34: =IFERROR(VLOOKUP(D34,Lookup_Departments!$A$2:$B$7,1,FALSE),"Invalid") -> IT02 | P34: =IF(ISNUMBER(E34),E34,DATE(RIGHT(E34,4),LEFT(E34,2),MID(E34,4,2))) -> 43626 | Q34: =DATEDIF(P34,TODAY(),"Y") -> 7 | R34: =IF(F34="",AVERAGEIF($D$2:$D$151,D34,$F$2:$F$151),F34) -> 90157 | S34: =IF(G34="",AVERAGE($G$2:$G$158),G34) -> 72 | T34: =_xlfn.XLOOKUP(S34,Lookup_Performance!$A$2:$A$6,Lookup_Performance!$C$2:$C$6,"Not Found",-1) -> Achieving | U34: =_xlfn.XLOOKUP(S34,Lookup_Performance!$A$2:$A$6,Lookup_Performance!$D$2:$D$6,"Not Found",-1) -> 0.05 | V34: =TRIM(CLEAN(UPPER(H34))) -> ACTIVE
A35: EMP125 | B35: Jane | C35: Martinez | D35: HR01 | E35: 44578 | F35: 59899 | G35: 58 | H35: active | J35: =TRIM(CLEAN(A35)) -> EMP125 | K35: =TRIM(CLEAN(PROPER(B35))) -> Jane | L35: =TRIM(CLEAN(PROPER(C35))) -> Martinez | M35: =_xlfn.TEXTJOIN(" ",TRUE,K35,L35) -> Jane Martinez | N35: =_xlfn.XLOOKUP(O35,Lookup_Departments!$A$2:$A$7,Lookup_Departments!$B$2:$B$7,"Not Found") -> Human Resources | O35: =IFERROR(VLOOKUP(D35,Lookup_Departments!$A$2:$B$7,1,FALSE),"Invalid") -> HR01 | P35: =IF(ISNUMBER(E35),E35,DATE(RIGHT(E35,4),LEFT(E35,2),MID(E35,4,2))) -> 44578 | Q35: =DATEDIF(P35,TODAY(),"Y") -> 4 | R35: =IF(F35="",AVERAGEIF($D$2:$D$151,D35,$F$2:$F$151),F35) -> 59899 | S35: =IF(G35="",AVERAGE($G$2:$G$158),G35) -> 58 | T35: =_xlfn.XLOOKUP(S35,Lookup_Performance!$A$2:$A$6,Lookup_Performance!$C$2:$C$6,"Not Found",-1) -> Developing | U35: =_xlfn.XLOOKUP(S35,Lookup_Performance!$A$2:$A$6,Lookup_Performance!$D$2:$D$6,"Not Found",-1) -> 0.02 | V35: =TRIM(CLEAN(UPPER(H35))) -> ACTIVE
A36: EMP085 | B36: Emily | C36: Jones | D36: FIN03 | E36: 42919 | F36: 113389 | G36: 78 | H36: ACTIVE | J36: =TRIM(CLEAN(A36)) -> EMP085 | K36: =TRIM(CLEAN(PROPER(B36))) -> Emily | L36: =TRIM(CLEAN(PROPER(C36))) -> Jones | M36: =_xlfn.TEXTJOIN(" ",TRUE,K36,L36) -> Emily Jones | N36: =_xlfn.XLOOKUP(O36,Lookup_Departments!$A$2:$A$7,Lookup_Departments!$B$2:$B$7,"Not Found") -> Finance | O36: =IFERROR(VLOOKUP(D36,Lookup_Departments!$A$2:$B$7,1,FALSE),"Invalid") -> FIN03 | P36: =IF(ISNUMBER(E36),E36,DATE(RIGHT(E36,4),LEFT(E36,2),MID(E36,4,2))) -> 42919 | Q36: =DATEDIF(P36,TODAY(),"Y") -> 9 | R36: =IF(F36="",AVERAGEIF($D$2:$D$151,D36,$F$2:$F$151),F36) -> 113389 | S36: =IF(G36="",AVERAGE($G$2:$G$158),G36) -> 78 | T36: =_xlfn.XLOOKUP(S36,Lookup_Performance!$A$2:$A$6,Lookup_Performance!$C$2:$C$6,"Not Found",-1) -> Achieving | U36: =_xlfn.XLOOKUP(S36,Lookup_Performance!$A$2:$A$6,Lookup_Performance!$D$2:$D$6,"Not Found",-1) -> 0.05 | V36: =TRIM(CLEAN(UPPER(H36))) -> ACTIVE
A37: EMP106 | B37: Unknown | C37: Brown | D37: IT02 | E37: 42248 | F37: 102691 | G37: 30 | H37: ACTIVE | J37: =TRIM(CLEAN(A37)) -> EMP106 | K37: =TRIM(CLEAN(PROPER(B37))) -> Unknown | L37: =TRIM(CLEAN(PROPER(C37))) -> Brown | M37: =_xlfn.TEXTJOIN(" ",TRUE,K37,L37) -> Unknown Brown | N37: =_xlfn.XLOOKUP(O37,Lookup_Departments!$A$2:$A$7,Lookup_Departments!$B$2:$B$7,"Not Found") -> Information Technology | O37: =IFERROR(VLOOKUP(D37,Lookup_Departments!$A$2:$B$7,1,FALSE),"Invalid") -> IT02 | P37: =IF(ISNUMBER(E37),E37,DATE(RIGHT(E37,4),LEFT(E37,2),MID(E37,4,2))) -> 42248 | Q37: =DATEDIF(P37,TODAY(),"Y") -> 10 | R37: =IF(F37="",AVERAGEIF($D$2:$D$151,D37,$F$2:$F$151),F37) -> 102691 | S37: =IF(G37="",AVERAGE($G$2:$G$158),G37) -> 30 | T37: =_xlfn.XLOOKUP(S37,Lookup_Performance!$A$2:$A$6,Lookup_Performance!$C$2:$C$6,"Not Found",-1) -> Needs Improvement | U37: =_xlfn.XLOOKUP(S37,Lookup_Performance!$A$2:$A$6,Lookup_Performance!$D$2:$D$6,"Not Found",-1) -> 0 | V37: =TRIM(CLEAN(UPPER(H37))) -> ACTIVE
A38: EMP043 | B38: John | C38: Wilson | D38: OPS06 | E38: 44776 | F38: 111845 | G38: 52 | H38: Active | J38: =TRIM(CLEAN(A38)) -> EMP043 | K38: =TRIM(CLEAN(PROPER(B38))) -> John | L38: =TRIM(CLEAN(PROPER(C38))) -> Wilson | M38: =_xlfn.TEXTJOIN(" ",TRUE,K38,L38) -> John Wilson | N38: =_xlfn.XLOOKUP(O38,Lookup_Departments!$A$2:$A$7,Lookup_Departments!$B$2:$B$7,"Not Found") -> Operations | O38: =IFERROR(VLOOKUP(D38,Lookup_Departments!$A$2:$B$7,1,FALSE),"Invalid") -> OPS06 | P38: =IF(ISNUMBER(E38),E38,DATE(RIGHT(E38,4),LEFT(E38,2),MID(E38,4,2))) -> 44776 | Q38: =DATEDIF(P38,TODAY(),"Y") -> 3 | R38: =IF(F38="",AVERAGEIF($D$2:$D$151,D38,$F$2:$F$151),F38) -> 111845 | S38: =IF(G38="",AVERAGE($G$2:$G$158),G38) -> 52 | T38: =_xlfn.XLOOKUP(S38,Lookup_Performance!$A$2:$A$6,Lookup_Performance!$C$2:$C$6,"Not Found",-1) -> Developing | U38: =_xlfn.XLOOKUP(S38,Lookup_Performance!$A$2:$A$6,Lookup_Performance!$D$2:$D$6,"Not Found",-1) -> 0.02 | V38: =TRIM(CLEAN(UPPER(H38))) -> ACTIVE
A39: EMP068 | B39: Melissa | C39: Brown | D39: SAL05 | E39: 06/29/2022 | F39: 69219 | G39: 98 | H39: active | J39: =TRIM(CLEAN(A39)) -> EMP068 | K39: =TRIM(CLEAN(PROPER(B39))) -> Melissa | L39: =TRIM(CLEAN(PROPER(C39))) -> Brown | M39: =_xlfn.TEXTJOIN(" ",TRUE,K39,L39) -> Melissa Brown | N39: =_xlfn.XLOOKUP(O39,Lookup_Departments!$A$2:$A$7,Lookup_Departments!$B$2:$B$7,"Not Found") -> Sales | O39: =IFERROR(VLOOKUP(D39,Lookup_Departments!$A$2:$B$7,1,FALSE),"Invalid") -> SAL05 | P39: =IF(ISNUMBER(E39),E39,DATE(RIGHT(E39,4),LEFT(E39,2),MID(E39,4,2))) -> 44741 | Q39: =DATEDIF(P39,TODAY(),"Y") -> 4 | R39: =IF(F39="",AVERAGEIF($D$2:$D$151,D39,$F$2:$F$151),F39) -> 69219 | S39: =IF(G39="",AVERAGE($G$2:$G$158),G39) -> 98 | T39: =_xlfn.XLOOKUP(S39,Lookup_Performance!$A$2:$A$6,Lookup_Performance!$C$2:$C$6,"Not Found",-1) -> Outstanding | U39: =_xlfn.XLOOKUP(S39,Lookup_Performance!$A$2:$A$6,Lookup_Performance!$D$2:$D$6,"Not Found",-1) -> 0.12 | V39: =TRIM(CLEAN(UPPER(H39))) -> ACTIVE
A40: EMP128 | B40: Michael | C40: Smith | D40: FIN03 | E40: 43949 | G40: 93 | H40: ACTIVE | J40: =TRIM(CLEAN(A40)) -> EMP128 | K40: =TRIM(CLEAN(PROPER(B40))) -> Michael | L40: =TRIM(CLEAN(PROPER(C40))) -> Smith | M40: =_xlfn.TEXTJOIN(" ",TRUE,K40,L40) -> Michael Smith | N40: =_xlfn.XLOOKUP(O40,Lookup_Departments!$A$2:$A$7,Lookup_Departments!$B$2:$B$7,"Not Found") -> Finance | O40: =IFERROR(VLOOKUP(D40,Lookup_Departments!$A$2:$B$7,1,FALSE),"Invalid") -> FIN03 | P40: =IF(ISNUMBER(E40),E40,DATE(RIGHT(E40,4),LEFT(E40,2),MID(E40,4,2))) -> 43949 | Q40: =DATEDIF(P40,TODAY(),"Y") -> 6 | R40: =IF(F40="",AVERAGEIF($D$2:$D$151,D40,$F$2:$F$151),F40) -> 87938.5 | S40: =IF(G40="",AVERAGE($G$2:$G$158),G40) -> 93 | T40: =_xlfn.XLOOKUP(S40,Lookup_Performance!$A$2:$A$6,Lookup_Performance!$C$2:$C$6,"Not Found",-1) -> Exceeding | U40: =_xlfn.XLOOKUP(S40,Lookup_Performance!$A$2:$A$6,Lookup_Performance!$D$2:$D$6,"Not Found",-1) -> 0.08 | V40: =TRIM(CLEAN(UPPER(H40))) -> ACTIVE
...

Sheet Raw_Employee_Data
A1: Emp ID | B1: First_Name | C1: Last_Name | D1: Dept Code | E1: Hire Date | F1: Salary | G1: Perf_Score | H1: Employment Status
A2: EMP127 | B2: Emily | C2: Brown | D2: IT02 | E2: 43093 | F2: 50361 | G2: 52 | H2: active
A3: EMP046 | B3: Richard | C3: Hernandez | D3: MKT04 | E3: 44659 | F3: 112673 | H3: ACTIVE
A4: EMP134 | B4: Emily | C4: Gonzalez | D4: IT02 | E4: 42431 | F4: $114,425 | G4: 54 | H4: LEFT
A5: EMP139 | B5: John | C5: Martinez | D5: FIN03 | E5: 45110 | F5: 103831 | G5: 70 | H5: active
A6: EMP112 | B6: Thomas | C6: Smith | D6: IT02 | E6: 44977 | F6: 73785 | G6: 40 | H6: Left
A7: EMP030 | B7: Emily | C7: Johnson | D7: OPS06 | E7: 43892 | F7: 115882 | G7: 49 | H7: ACTIVE
A8: EMP096 | B8: John | C8: Wilson | D8: OPS06 | E8: 45272 | F8: 59980 | G8: 70 | H8: Left
A9: EMP098 | B9: Jessica | C9: Smith | D9: OPS06 | E9: 44174 | F9: 68728 | G9: 45 | H9: ACTIVE
A10: EMP095 | C10: Rodriguez | D10: FIN03 | E10: 43107 | F10: 102139 | G10: 79 | H10: active
A11: EMP140 | B11: Michael | C11: Martinez | D11: SAL05 | E11: 42676 | F11: 94998 | G11: 58 | H11: Active
A12: EMP020 | B12: Emily | C12: Miller | D12: sal05 | E12: 43911 | F12: $118,635 | G12: 49 | H12: Active
A13: EMP057 | B13: Emily | C13: Hernandez | D13: IT02 | E13: 42425 | F13: 76918 | G13: 62 | H13: Actv
A14: EMP016 | B14: Jane | C14: Williams | D14: mkt04 | E14: 44364 | F14: 61408 | G14: 48 | H14: ACTIVE
A15: EMP070 | B15: Jane | C15: Miller | D15: MKT04 | E15: 44001 | F15: 99990 | G15: 54 | H15: Actv
A16: EMP025 | B16: Robert | C16: Jones | D16: MKT04 | E16: 43820 | F16: 80385 | H16: active
A17: EMP031 | B17: Thomas | C17: Rodriguez | D17: SAL05 | E17: 45169 | F17: 65290 | G17: 77 | H17: active
A18: EMP126 | B18: Emily | C18: Davis | D18: IT02 | E18: 42337 | F18: 105765 | G18: 42 | H18: Active
A19: EMP109 | B19: James | C19: Martinez | D19: SAL05 | E19: 42899 | F19: 102921 | G19: 49 | H19: ACTIVE
A20: EMP066 | B20: Ashley | C20: Lopez | D20: MKT04 | E20: 43235 | F20: 73984 | G20: 93 | H20: Actv
A21: EMP120 | B21: Amanda | C21: Gonzalez | D21: IT02 | E21: 42575 | G21: 75 | H21: Actv
A22: EMP019 | B22: Michael | C22: Hernandez | D22: FIN03 | E22: 43076 | F22: 118527 | G22: 50 | H22: Actv
A23: EMP013 | B23: Richard | C23: Hernandez | D23: MKT04 | E23: 44353 | F23: 107871 | G23: 88 | H23: active
A24: EMP010 | B24: Michael | C24: Rodriguez | D24: IT02 | E24: 44815 | F24: 93956 | G24: 50 | H24: LEFT
A25: EMP032 | B25: Jessica | C25: Johnson | D25: FIN03 | E25: 42565 | F25: 100851 | G25: 64 | H25: ACTIVE
A26: EMP082 | B26: Ashley | C26: Williams | D26: SAL05 | E26: 44728 | F26: 68655 | G26: 32 | H26: active
A27: EMP052 | C27: Williams | D27: SAL05 | E27: 45134 | F27: 81205 | G27: 59 | H27: Actv
A28: EMP129 | B28: John | C28: Wilson | D28: SAL05 | E28: 09/24/2019 | F28: $77,610 | G28: 88 | H28: Actv
A29: EMP146 | B29: Thomas | C29: Rodriguez | D29: it02 | E29: 44765 | F29: $50,873 | G29: 90 | H29: Active
A30: EMP099 | B30: Michael | C30: Wilson | D30: fin03 | E30: 43233 | F30: 85312 | G30: 66 | H30: active
A31: EMP015 | B31: John | C31: Rodriguez | D31: SAL05 | E31: 42202 | G31: 68 | H31: active
A32: EMP076 | B32: Thomas | C32: Hernandez | D32: OPS06 | E32: 42221 | F32: 97055 | G32: 80 | H32: Actv
A33: EMP137 | B33: Michael | C33: Johnson | D33: IT02 | E33: 45195 | F33: 66069 | G33: 72 | H33: Actv
A34: EMP056 | B34: Sarah | C34: Brown | D34: it02 | E34: 43626 | F34: 90157 | G34: 58 | H34: active
A35: EMP125 | B35: Jane | C35: Martinez | D35: HR01 | E35: 44578 | F35: 59899 | G35: 78 | H35: Actv
A36: EMP085 | B36: Emily | C36: Jones | D36: FIN03 | E36: 42919 | F36: 113389 | G36: 30 | H36: ACTIVE
A37: EMP106 | C37: Brown | D37: IT02 | E37: 42248 | F37: 102691 | G37: 52 | H37: Active
A38: EMP043 | B38: John | C38: Wilson | D38: OPS06 | E38: 44776 | F38: 111845 | G38: 98 | H38: active
A39: EMP068 | B39: Melissa | C39: Brown | D39: SAL05 | E39: 06/29/2022 | F39: 69219 | G39: 93 | H39: Actv
A40: EMP128 | B40: Michael | C40: Smith | D40: FIN03 | E40: 43949 | G40: 80 | H40: left
...

Sheet Lookup_Departments
A1: Dept_Code | B1: Department_Name
A2: HR01 | B2: Human Resources
A3: IT02 | B3: Information Technology
A4: FIN03 | B4: Finance
A5: MKT04 | B5: Marketing
A6: SAL05 | B6: Sales
A7: OPS06 | B7: Operations

Sheet Lookup_Performance
A1: Min_Score | B1: Max_Score | C1: Performance_Band | D1: Bonus_Percentage
A2: 0 | B2: 49 | C2: Needs Improvement | D2: 0
A3: 50 | B3: 69 | C3: Developing | D3: 0.02
A4: 70 | B4: 84 | C4: Achieving | D4: 0.05
A5: 85 | B5: 94 | C5: Exceeding | D5: 0.08
A6: 95 | B6: 100 | C6: Outstanding | D6: 0.12
